[2025-06-05 02:26:34.210583] [tm_devices] [   DEBUG] timezone==Europe/Rome
[2025-06-05 02:26:34.210997] [tm_devices] [   DEBUG] tm_devices==3.2.0
[2025-06-05 02:26:34.211049] [tm_devices] [    INFO] Opening DeviceManager
[2025-06-05 02:26:34.487836] [tm_devices] [CRITICAL] cannot import name 'process_block_directory' from 'captain.utils.manifest.build_manifest' (/Users/emanuelesabetta/Code/ATLASVIBE/atlasvibe/captain/utils/manifest/build_manifest.py)

An uncaught exception occurred. If the exception was explicitly raised by the tm_devices package, look for the most recent previous ERROR log entry above to see the specific timestamp of the exception. Otherwise, use the traceback to debug the issue.

Traceback (most recent call last):
  File "/Users/emanuelesabetta/Code/ATLASVIBE/atlasvibe/main.py", line 19, in <module>
    uvicorn.run(
  File "/Users/emanuelesabetta/Code/ATLASVIBE/atlasvibe/.venv/lib/python3.11/site-packages/uvicorn/main.py", line 579, in run
    server.run()
  File "/Users/emanuelesabetta/Code/ATLASVIBE/atlasvibe/.venv/lib/python3.11/site-packages/uvicorn/server.py", line 65, in run
    return asyncio.run(self.serve(sockets=sockets))
           ^^^^^^^^^^^^^^^^^^^^^^^^^^^^^^^^^^^^^^^^
  File "/Users/emanuelesabetta/.local/share/uv/python/cpython-3.11.12-macos-aarch64-none/lib/python3.11/asyncio/runners.py", line 190, in run
    return runner.run(main)
           ^^^^^^^^^^^^^^^^
  File "/Users/emanuelesabetta/.local/share/uv/python/cpython-3.11.12-macos-aarch64-none/lib/python3.11/asyncio/runners.py", line 118, in run
    return self._loop.run_until_complete(task)
           ^^^^^^^^^^^^^^^^^^^^^^^^^^^^^^^^^^^
  File "uvloop/loop.pyx", line 1518, in uvloop.loop.Loop.run_until_complete
  File "/Users/emanuelesabetta/Code/ATLASVIBE/atlasvibe/.venv/lib/python3.11/site-packages/uvicorn/server.py", line 69, in serve
    await self._serve(sockets)
  File "/Users/emanuelesabetta/Code/ATLASVIBE/atlasvibe/.venv/lib/python3.11/site-packages/uvicorn/server.py", line 76, in _serve
    config.load()
  File "/Users/emanuelesabetta/Code/ATLASVIBE/atlasvibe/.venv/lib/python3.11/site-packages/uvicorn/config.py", line 434, in load
    self.loaded_app = import_from_string(self.app)
                      ^^^^^^^^^^^^^^^^^^^^^^^^^^^^
  File "/Users/emanuelesabetta/Code/ATLASVIBE/atlasvibe/.venv/lib/python3.11/site-packages/uvicorn/importer.py", line 19, in import_from_string
    module = importlib.import_module(module_str)
             ^^^^^^^^^^^^^^^^^^^^^^^^^^^^^^^^^^^
  File "/Users/emanuelesabetta/.local/share/uv/python/cpython-3.11.12-macos-aarch64-none/lib/python3.11/importlib/__init__.py", line 126, in import_module
    return _bootstrap._gcd_import(name[level:], package, level)
           ^^^^^^^^^^^^^^^^^^^^^^^^^^^^^^^^^^^^^^^^^^^^^^^^^^^^
  File "<frozen importlib._bootstrap>", line 1204, in _gcd_import
  File "<frozen importlib._bootstrap>", line 1176, in _find_and_load
  File "<frozen importlib._bootstrap>", line 1147, in _find_and_load_unlocked
  File "<frozen importlib._bootstrap>", line 690, in _load_unlocked
  File "<frozen importlib._bootstrap_external>", line 940, in exec_module
  File "<frozen importlib._bootstrap>", line 241, in _call_with_frames_removed
  File "/Users/emanuelesabetta/Code/ATLASVIBE/atlasvibe/captain/main.py", line 4, in <module>
    from captain.routes import (
  File "/Users/emanuelesabetta/Code/ATLASVIBE/atlasvibe/captain/routes/blocks.py", line 19, in <module>
    from captain.utils.manifest.build_manifest import process_block_directory
ImportError: cannot import name 'process_block_directory' from 'captain.utils.manifest.build_manifest' (/Users/emanuelesabetta/Code/ATLASVIBE/atlasvibe/captain/utils/manifest/build_manifest.py)
